
import React, { Component, ErrorInfo, ReactNode } from 'react';
import { Card, CardContent, CardHeader, CardTitle } from '@/components/ui/card';
import { Button } from '@/components/ui/button';
import { AlertTriangle, RefreshCw } from 'lucide-react';

interface Props {
  children: ReactNode;
  fallback?: ReactNode;
}

interface State {
  hasError: boolean;
  error: Error | null;
  errorInfo: ErrorInfo | null;
}

export class ErrorBoundary extends Component<Props, State> {
  public state: State = {
    hasError: false,
    error: null,
    errorInfo: null
  };

  public static getDerivedStateFromError(error: Error): State {
    return {
      hasError: true,
      error,
      errorInfo: null
    };
  }

  public componentDidCatch(error: Error, errorInfo: ErrorInfo) {
    console.error('ErrorBoundary caught an error:', error, errorInfo);
    
    this.setState({
      error,
      errorInfo
    });

    // Log to external service in production
    if (process.env.NODE_ENV === 'production') {
      // You can integrate with error reporting services here
      console.error('Production error:', {
        error: error.message,
        stack: error.stack,
        componentStack: errorInfo.componentStack
      });
    }
  }

  private handleReset = () => {
    this.setState({
      hasError: false,
      error: null,
      errorInfo: null
    });
  };

  private handleReload = () => {
    window.location.reload();
  };

  public render() {
    if (this.state.hasError) {
      if (this.props.fallback) {
        return this.props.fallback;
      }

      return (
        <div className="min-h-screen bg-background flex items-center justify-center p-4">
          <Card className="w-full max-w-lg">
            <CardHeader>
              <CardTitle className="flex items-center gap-2 text-destructive">
                <AlertTriangle className="h-5 w-5" />
                Something went wrong
              </CardTitle>
            </CardHeader>
            <CardContent className="space-y-4">
              <p className="text-muted-foreground">
                We encountered an unexpected error. This has been logged and we'll look into it.
              </p>
              
              {process.env.NODE_ENV === 'development' && this.state.error && (
                <details className="bg-muted p-4 rounded-lg">
                  <summary className="cursor-pointer font-medium mb-2">
                    Error Details (Development Only)
                  </summary>
                  <div className="text-sm space-y-2">
                    <div>
                      <strong>Error:</strong> {this.state.error.message}
                    </div>
                    {this.state.error.stack && (
                      <div>
                        <strong>Stack Trace:</strong>
                        <pre className="text-xs overflow-auto max-h-40 mt-1">
                          {this.state.error.stack}
                        </pre>
                      </div>
                    )}
                    {this.state.errorInfo?.componentStack && (
                      <div>
                        <strong>Component Stack:</strong>
                        <pre className="text-xs overflow-auto max-h-40 mt-1">
                          {this.state.errorInfo.componentStack}
                        </pre>
                      </div>
                    )}
                  </div>
                </details>
              )}

              <div className="flex gap-2">
                <Button onClick={this.handleReset} variant="outline">
                  <RefreshCw className="h-4 w-4 mr-2" />
                  Try Again
                </Button>
                <Button onClick={this.handleReload}>
                  Reload Page
                </Button>
              </div>
            </CardContent>
          </Card>
        </div>
      );
    }

    return this.props.children;
  }
}

// Hook version for functional components
export const useErrorHandler = () => {
  const handleError = React.useCallback((error: Error, errorInfo?: string) => {
    console.error('Error caught by useErrorHandler:', error);
    
    if (process.env.NODE_ENV === 'production') {
      // Log to external service
      console.error('Production error:', {
        error: error.message,
        stack: error.stack,
        info: errorInfo
      });
    }
  }, []);

  return handleError;
};
